DEBUG    faker.factory:factory.py:76 Looking for locale `en_US` in provider `faker.providers.address`.
DEBUG    faker.factory:factory.py:95 Provider `faker.providers.address` has been localized to `en_US`.
DEBUG    faker.factory:factory.py:76 Looking for locale `en_US` in provider `faker.providers.automotive`.
DEBUG    faker.factory:factory.py:95 Provider `faker.providers.automotive` has been localized to `en_US`.
DEBUG    faker.factory:factory.py:76 Looking for locale `en_US` in provider `faker.providers.bank`.
DEBUG    faker.factory:factory.py:86 Specified locale `en_US` is not available for provider `faker.providers.bank`. Locale reset to `en_GB` for this provider.
DEBUG    faker.factory:factory.py:76 Looking for locale `en_US` in provider `faker.providers.barcode`.
DEBUG    faker.factory:factory.py:95 Provider `faker.providers.barcode` has been localized to `en_US`.
DEBUG    faker.factory:factory.py:76 Looking for locale `en_US` in provider `faker.providers.color`.
DEBUG    faker.factory:factory.py:95 Provider `faker.providers.color` has been localized to `en_US`.
DEBUG    faker.factory:factory.py:76 Looking for locale `en_US` in provider `faker.providers.company`.
DEBUG    faker.factory:factory.py:95 Provider `faker.providers.company` has been localized to `en_US`.
DEBUG    faker.factory:factory.py:76 Looking for locale `en_US` in provider `faker.providers.credit_card`.
DEBUG    faker.factory:factory.py:95 Provider `faker.providers.credit_card` has been localized to `en_US`.
DEBUG    faker.factory:factory.py:76 Looking for locale `en_US` in provider `faker.providers.currency`.
DEBUG    faker.factory:factory.py:95 Provider `faker.providers.currency` has been localized to `en_US`.
DEBUG    faker.factory:factory.py:76 Looking for locale `en_US` in provider `faker.providers.date_time`.
DEBUG    faker.factory:factory.py:95 Provider `faker.providers.date_time` has been localized to `en_US`.
DEBUG    faker.factory:factory.py:106 Provider `faker.providers.emoji` does not feature localization. Specified locale `en_US` is not utilized for this provider.
DEBUG    faker.factory:factory.py:106 Provider `faker.providers.file` does not feature localization. Specified locale `en_US` is not utilized for this provider.
DEBUG    faker.factory:factory.py:76 Looking for locale `en_US` in provider `faker.providers.geo`.
DEBUG    faker.factory:factory.py:95 Provider `faker.providers.geo` has been localized to `en_US`.
DEBUG    faker.factory:factory.py:76 Looking for locale `en_US` in provider `faker.providers.internet`.
DEBUG    faker.factory:factory.py:95 Provider `faker.providers.internet` has been localized to `en_US`.
DEBUG    faker.factory:factory.py:76 Looking for locale `en_US` in provider `faker.providers.isbn`.
DEBUG    faker.factory:factory.py:95 Provider `faker.providers.isbn` has been localized to `en_US`.
DEBUG    faker.factory:factory.py:76 Looking for locale `en_US` in provider `faker.providers.job`.
DEBUG    faker.factory:factory.py:95 Provider `faker.providers.job` has been localized to `en_US`.
DEBUG    faker.factory:factory.py:76 Looking for locale `en_US` in provider `faker.providers.lorem`.
DEBUG    faker.factory:factory.py:95 Provider `faker.providers.lorem` has been localized to `en_US`.
DEBUG    faker.factory:factory.py:76 Looking for locale `en_US` in provider `faker.providers.misc`.
DEBUG    faker.factory:factory.py:95 Provider `faker.providers.misc` has been localized to `en_US`.
DEBUG    faker.factory:factory.py:76 Looking for locale `en_US` in provider `faker.providers.passport`.
DEBUG    faker.factory:factory.py:95 Provider `faker.providers.passport` has been localized to `en_US`.
DEBUG    faker.factory:factory.py:76 Looking for locale `en_US` in provider `faker.providers.person`.
DEBUG    faker.factory:factory.py:95 Provider `faker.providers.person` has been localized to `en_US`.
DEBUG    faker.factory:factory.py:76 Looking for locale `en_US` in provider `faker.providers.phone_number`.
DEBUG    faker.factory:factory.py:95 Provider `faker.providers.phone_number` has been localized to `en_US`.
DEBUG    faker.factory:factory.py:106 Provider `faker.providers.profile` does not feature localization. Specified locale `en_US` is not utilized for this provider.
DEBUG    faker.factory:factory.py:106 Provider `faker.providers.python` does not feature localization. Specified locale `en_US` is not utilized for this provider.
DEBUG    faker.factory:factory.py:106 Provider `faker.providers.sbn` does not feature localization. Specified locale `en_US` is not utilized for this provider.
DEBUG    faker.factory:factory.py:76 Looking for locale `en_US` in provider `faker.providers.ssn`.
DEBUG    faker.factory:factory.py:95 Provider `faker.providers.ssn` has been localized to `en_US`.
DEBUG    faker.factory:factory.py:106 Provider `faker.providers.user_agent` does not feature localization. Specified locale `en_US` is not utilized for this provider.
DEBUG    selenium.webdriver.common.selenium_manager:selenium_manager.py:101 Selenium Manager binary found at: /opt/hostedtoolcache/Python/3.12.6/x64/lib/python3.12/site-packages/selenium/webdriver/common/linux/selenium-manager
DEBUG    selenium.webdriver.common.selenium_manager:selenium_manager.py:114 Executing process: /opt/hostedtoolcache/Python/3.12.6/x64/lib/python3.12/site-packages/selenium/webdriver/common/linux/selenium-manager --browser chrome --debug --language-binding python --output json
DEBUG    selenium.webdriver.common.selenium_manager:selenium_manager.py:140 Sending stats to Plausible: Props { browser: "chrome", browser_version: "", os: "linux", arch: "x86_64", lang: "python", selenium_version: "4.24" }
DEBUG    selenium.webdriver.common.selenium_manager:selenium_manager.py:140 Found chromedriver 127.0.6533.119 in PATH: /opt/hostedtoolcache/setup-chrome/chromedriver/127.0.6533.119/x64/chromedriver
DEBUG    selenium.webdriver.common.selenium_manager:selenium_manager.py:140 chrome detected at /usr/bin/google-chrome
DEBUG    selenium.webdriver.common.selenium_manager:selenium_manager.py:140 Running command: /usr/bin/google-chrome --version
DEBUG    selenium.webdriver.common.selenium_manager:selenium_manager.py:140 Output: "Google Chrome 129.0.6668.58 "
DEBUG    selenium.webdriver.common.selenium_manager:selenium_manager.py:140 Detected browser: chrome 129.0.6668.58
DEBUG    selenium.webdriver.common.selenium_manager:selenium_manager.py:140 Discovering versions from https://googlechromelabs.github.io/chrome-for-testing/known-good-versions-with-downloads.json
DEBUG    selenium.webdriver.common.selenium_manager:selenium_manager.py:140 Required driver: chromedriver 129.0.6668.70
WARNING  selenium.webdriver.common.selenium_manager:selenium_manager.py:138 The chromedriver version (127.0.6533.119) detected in PATH at /opt/hostedtoolcache/setup-chrome/chromedriver/127.0.6533.119/x64/chromedriver might not be compatible with the detected chrome version (129.0.6668.58); currently, chromedriver 129.0.6668.70 is recommended for chrome 129.*, so it is advised to delete the driver in PATH and retry
DEBUG    selenium.webdriver.common.selenium_manager:selenium_manager.py:140 Driver path: /opt/hostedtoolcache/setup-chrome/chromedriver/127.0.6533.119/x64/chromedriver
DEBUG    selenium.webdriver.common.selenium_manager:selenium_manager.py:140 Browser path: /usr/bin/google-chrome
DEBUG    selenium.webdriver.common.service:service.py:219 Started executable: `/opt/hostedtoolcache/setup-chrome/chromedriver/127.0.6533.119/x64/chromedriver` in a child process with pid: 2416 using 0 to output -3
DEBUG    selenium.webdriver.remote.remote_connection:remote_connection.py:305 POST http://localhost:52489/session {'capabilities': {'firstMatch': [{}], 'alwaysMatch': {'browserName': 'chrome', 'pageLoadStrategy': <PageLoadStrategy.normal: 'normal'>, 'browserVersion': None, 'goog:chromeOptions': {'extensions': [], 'binary': '/usr/bin/google-chrome', 'args': ['--headless', '--window-size=1920,1080']}}}}
DEBUG    urllib3.connectionpool:connectionpool.py:243 Starting new HTTP connection (1): localhost:52489
DEBUG    urllib3.connectionpool:connectionpool.py:546 http://localhost:52489 "POST /session HTTP/11" 500 0
DEBUG    selenium.webdriver.remote.remote_connection:remote_connection.py:334 Remote response: status=500 | data={"value":{"error":"session not created","message":"session not created: This version of ChromeDriver only supports Chrome version 127\nCurrent browser version is 129.0.6668.58 with binary path /usr/bin/google-chrome","stacktrace":"#0 0x55fdab1a36ca \u003Cunknown>\n#1 0x55fdaae74600 \u003Cunknown>\n#2 0x55fdaaeb313c \u003Cunknown>\n#3 0x55fdaaeb20b2 \u003Cunknown>\n#4 0x55fdaaeacf24 \u003Cunknown>\n#5 0x55fdaaea82f8 \u003Cunknown>\n#6 0x55fdaaef2ce8 \u003Cunknown>\n#7 0x55fdaaee6643 \u003Cunknown>\n#8 0x55fdaaeb6d31 \u003Cunknown>\n#9 0x55fdaaeb779e \u003Cunknown>\n#10 0x55fdab16b25b \u003Cunknown>\n#11 0x55fdab16f1f2 \u003Cunknown>\n#12 0x55fdab158615 \u003Cunknown>\n#13 0x55fdab16fd82 \u003Cunknown>\n#14 0x55fdab13d25f \u003Cunknown>\n#15 0x55fdab192e68 \u003Cunknown>\n#16 0x55fdab193040 \u003Cunknown>\n#17 0x55fdab1a249c \u003Cunknown>\n#18 0x7f2429294ac3 \u003Cunknown>\n"}} | headers=HTTPHeaderDict({'Content-Length': '889', 'Content-Type': 'application/json; charset=utf-8', 'cache-control': 'no-cache'})
DEBUG    selenium.webdriver.remote.remote_connection:remote_connection.py:361 Finished Request
DEBUG    selenium.webdriver.common.selenium_manager:selenium_manager.py:101 Selenium Manager binary found at: /opt/hostedtoolcache/Python/3.12.6/x64/lib/python3.12/site-packages/selenium/webdriver/common/linux/selenium-manager
DEBUG    selenium.webdriver.common.selenium_manager:selenium_manager.py:114 Executing process: /opt/hostedtoolcache/Python/3.12.6/x64/lib/python3.12/site-packages/selenium/webdriver/common/linux/selenium-manager --browser chrome --debug --language-binding python --output json
DEBUG    selenium.webdriver.common.selenium_manager:selenium_manager.py:140 Found chromedriver 127.0.6533.119 in PATH: /opt/hostedtoolcache/setup-chrome/chromedriver/127.0.6533.119/x64/chromedriver
DEBUG    selenium.webdriver.common.selenium_manager:selenium_manager.py:140 chrome detected at /usr/bin/google-chrome
DEBUG    selenium.webdriver.common.selenium_manager:selenium_manager.py:140 Running command: /usr/bin/google-chrome --version
DEBUG    selenium.webdriver.common.selenium_manager:selenium_manager.py:140 Output: "Google Chrome 129.0.6668.58 "
DEBUG    selenium.webdriver.common.selenium_manager:selenium_manager.py:140 Detected browser: chrome 129.0.6668.58
DEBUG    selenium.webdriver.common.selenium_manager:selenium_manager.py:140 Required driver: chromedriver 129.0.6668.70
WARNING  selenium.webdriver.common.selenium_manager:selenium_manager.py:138 The chromedriver version (127.0.6533.119) detected in PATH at /opt/hostedtoolcache/setup-chrome/chromedriver/127.0.6533.119/x64/chromedriver might not be compatible with the detected chrome version (129.0.6668.58); currently, chromedriver 129.0.6668.70 is recommended for chrome 129.*, so it is advised to delete the driver in PATH and retry
DEBUG    selenium.webdriver.common.selenium_manager:selenium_manager.py:140 Driver path: /opt/hostedtoolcache/setup-chrome/chromedriver/127.0.6533.119/x64/chromedriver
DEBUG    selenium.webdriver.common.selenium_manager:selenium_manager.py:140 Browser path: /usr/bin/google-chrome
DEBUG    selenium.webdriver.common.service:service.py:219 Started executable: `/opt/hostedtoolcache/setup-chrome/chromedriver/127.0.6533.119/x64/chromedriver` in a child process with pid: 2857 using 0 to output -3
DEBUG    selenium.webdriver.remote.remote_connection:remote_connection.py:305 POST http://localhost:58577/session {'capabilities': {'firstMatch': [{}], 'alwaysMatch': {'browserName': 'chrome', 'pageLoadStrategy': <PageLoadStrategy.normal: 'normal'>, 'browserVersion': None, 'goog:chromeOptions': {'extensions': [], 'binary': '/usr/bin/google-chrome', 'args': ['--headless', '--window-size=1920,1080']}}}}
DEBUG    urllib3.connectionpool:connectionpool.py:243 Starting new HTTP connection (1): localhost:58577
DEBUG    urllib3.connectionpool:connectionpool.py:546 http://localhost:58577 "POST /session HTTP/11" 500 0
DEBUG    selenium.webdriver.remote.remote_connection:remote_connection.py:334 Remote response: status=500 | data={"value":{"error":"session not created","message":"session not created: This version of ChromeDriver only supports Chrome version 127\nCurrent browser version is 129.0.6668.58 with binary path /usr/bin/google-chrome","stacktrace":"#0 0x55dd826816ca \u003Cunknown>\n#1 0x55dd82352600 \u003Cunknown>\n#2 0x55dd8239113c \u003Cunknown>\n#3 0x55dd823900b2 \u003Cunknown>\n#4 0x55dd8238af24 \u003Cunknown>\n#5 0x55dd823862f8 \u003Cunknown>\n#6 0x55dd823d0ce8 \u003Cunknown>\n#7 0x55dd823c4643 \u003Cunknown>\n#8 0x55dd82394d31 \u003Cunknown>\n#9 0x55dd8239579e \u003Cunknown>\n#10 0x55dd8264925b \u003Cunknown>\n#11 0x55dd8264d1f2 \u003Cunknown>\n#12 0x55dd82636615 \u003Cunknown>\n#13 0x55dd8264dd82 \u003Cunknown>\n#14 0x55dd8261b25f \u003Cunknown>\n#15 0x55dd82670e68 \u003Cunknown>\n#16 0x55dd82671040 \u003Cunknown>\n#17 0x55dd8268049c \u003Cunknown>\n#18 0x7fd1cb494ac3 \u003Cunknown>\n"}} | headers=HTTPHeaderDict({'Content-Length': '889', 'Content-Type': 'application/json; charset=utf-8', 'cache-control': 'no-cache'})
DEBUG    selenium.webdriver.remote.remote_connection:remote_connection.py:361 Finished Request